[2024-12-11T21:18:06.645+0000] {local_task_job_runner.py:123} INFO - ::group::Pre task execution logs
[2024-12-11T21:18:06.660+0000] {taskinstance.py:2613} INFO - Dependencies all met for dep_context=non-requeueable deps ti=<TaskInstance: fetch_and_store_google_books.create_table scheduled__2024-06-24T00:00:00+00:00 [queued]>
[2024-12-11T21:18:06.668+0000] {taskinstance.py:2613} INFO - Dependencies all met for dep_context=requeueable deps ti=<TaskInstance: fetch_and_store_google_books.create_table scheduled__2024-06-24T00:00:00+00:00 [queued]>
[2024-12-11T21:18:06.668+0000] {taskinstance.py:2866} INFO - Starting attempt 2 of 2
[2024-12-11T21:18:06.679+0000] {taskinstance.py:2889} INFO - Executing <Task(PostgresOperator): create_table> on 2024-06-24 00:00:00+00:00
[2024-12-11T21:18:06.689+0000] {warnings.py:112} WARNING - /home/***/.local/lib/python3.12/site-packages/***/task/task_runner/standard_task_runner.py:70: DeprecationWarning: This process (pid=301) is multi-threaded, use of fork() may lead to deadlocks in the child.
  pid = os.fork()

[2024-12-11T21:18:06.690+0000] {standard_task_runner.py:72} INFO - Started process 307 to run task
[2024-12-11T21:18:06.691+0000] {standard_task_runner.py:104} INFO - Running: ['***', 'tasks', 'run', 'fetch_and_store_google_books', 'create_table', 'scheduled__2024-06-24T00:00:00+00:00', '--job-id', '695', '--raw', '--subdir', 'DAGS_FOLDER/dag2.py', '--cfg-path', '/tmp/tmpjmtbjb35']
[2024-12-11T21:18:06.692+0000] {standard_task_runner.py:105} INFO - Job 695: Subtask create_table
[2024-12-11T21:18:06.732+0000] {task_command.py:467} INFO - Running <TaskInstance: fetch_and_store_google_books.create_table scheduled__2024-06-24T00:00:00+00:00 [running]> on host bb74d1700244
[2024-12-11T21:18:06.801+0000] {taskinstance.py:3132} INFO - Exporting env vars: AIRFLOW_CTX_DAG_OWNER='***' AIRFLOW_CTX_DAG_ID='fetch_and_store_google_books' AIRFLOW_CTX_TASK_ID='create_table' AIRFLOW_CTX_EXECUTION_DATE='2024-06-24T00:00:00+00:00' AIRFLOW_CTX_TRY_NUMBER='2' AIRFLOW_CTX_DAG_RUN_ID='scheduled__2024-06-24T00:00:00+00:00'
[2024-12-11T21:18:06.802+0000] {logging_mixin.py:190} INFO - Task instance is in running state
[2024-12-11T21:18:06.803+0000] {logging_mixin.py:190} INFO -  Previous state of the Task instance: queued
[2024-12-11T21:18:06.803+0000] {logging_mixin.py:190} INFO - Current task name:create_table state:running start_date:2024-12-11 21:18:06.661466+00:00
[2024-12-11T21:18:06.803+0000] {logging_mixin.py:190} INFO - Dag name:fetch_and_store_google_books and current dag run status:running
[2024-12-11T21:18:06.804+0000] {taskinstance.py:731} INFO - ::endgroup::
[2024-12-11T21:18:06.804+0000] {sql.py:278} INFO - Executing:  
        CREATE TABLE IF NOT EXISTS google_books (
            id SERIAL PRIMARY KEY,
            title TEXT NOT NULL,
            authors TEXT,
            price TEXT,
            rating TEXT,
            link TEXT
        );
        
[2024-12-11T21:18:06.811+0000] {base.py:84} INFO - Retrieving connection 'books_connection2'
[2024-12-11T21:18:06.818+0000] {base.py:84} INFO - Retrieving connection 'books_connection2'
[2024-12-11T21:18:06.821+0000] {taskinstance.py:3311} ERROR - Task failed with exception
Traceback (most recent call last):
  File "/home/airflow/.local/lib/python3.12/site-packages/airflow/models/taskinstance.py", line 767, in _execute_task
    result = _execute_callable(context=context, **execute_callable_kwargs)
             ^^^^^^^^^^^^^^^^^^^^^^^^^^^^^^^^^^^^^^^^^^^^^^^^^^^^^^^^^^^^^
  File "/home/airflow/.local/lib/python3.12/site-packages/airflow/models/taskinstance.py", line 733, in _execute_callable
    return ExecutionCallableRunner(
           ^^^^^^^^^^^^^^^^^^^^^^^^
  File "/home/airflow/.local/lib/python3.12/site-packages/airflow/utils/operator_helpers.py", line 252, in run
    return self.func(*args, **kwargs)
           ^^^^^^^^^^^^^^^^^^^^^^^^^^
  File "/home/airflow/.local/lib/python3.12/site-packages/airflow/models/baseoperator.py", line 417, in wrapper
    return func(self, *args, **kwargs)
           ^^^^^^^^^^^^^^^^^^^^^^^^^^^
  File "/home/airflow/.local/lib/python3.12/site-packages/airflow/providers/common/sql/operators/sql.py", line 284, in execute
    output = hook.run(
             ^^^^^^^^^
  File "/home/airflow/.local/lib/python3.12/site-packages/airflow/providers/common/sql/hooks/sql.py", line 485, in run
    with self._create_autocommit_connection(autocommit) as conn:
         ^^^^^^^^^^^^^^^^^^^^^^^^^^^^^^^^^^^^^^^^^^^^^^
  File "/usr/local/lib/python3.12/contextlib.py", line 137, in __enter__
    return next(self.gen)
           ^^^^^^^^^^^^^^
  File "/home/airflow/.local/lib/python3.12/site-packages/airflow/providers/common/sql/hooks/sql.py", line 609, in _create_autocommit_connection
    with closing(self.get_conn()) as conn:
                 ^^^^^^^^^^^^^^^
  File "/home/airflow/.local/lib/python3.12/site-packages/airflow/providers/postgres/hooks/postgres.py", line 181, in get_conn
    self.conn = psycopg2.connect(**conn_args)
                ^^^^^^^^^^^^^^^^^^^^^^^^^^^^^
  File "/home/airflow/.local/lib/python3.12/site-packages/psycopg2/__init__.py", line 122, in connect
    conn = _connect(dsn, connection_factory=connection_factory, **kwasync)
           ^^^^^^^^^^^^^^^^^^^^^^^^^^^^^^^^^^^^^^^^^^^^^^^^^^^^^^^^^^^^^^^
psycopg2.OperationalError: connection to server at "172.18.0.3", port 5432 failed: FATAL:  database "google_books" does not exist

[2024-12-11T21:18:06.830+0000] {logging_mixin.py:190} INFO - Task instance in failure state
[2024-12-11T21:18:06.830+0000] {logging_mixin.py:190} INFO - Task start:2024-12-11 21:18:06.661466+00:00 end:2024-12-11 21:18:06.830062+00:00 duration:0.168596
[2024-12-11T21:18:06.831+0000] {logging_mixin.py:190} INFO - Task:<Task(PostgresOperator): create_table> dag:<DAG: fetch_and_store_google_books> dagrun:<DagRun fetch_and_store_google_books @ 2024-06-24 00:00:00+00:00: scheduled__2024-06-24T00:00:00+00:00, state:running, queued_at: 2024-12-11 21:12:15.949700+00:00. externally triggered: False>
[2024-12-11T21:18:06.831+0000] {logging_mixin.py:190} INFO - Failure caused by connection to server at "172.18.0.3", port 5432 failed: FATAL:  database "google_books" does not exist
[2024-12-11T21:18:06.832+0000] {taskinstance.py:1225} INFO - Marking task as FAILED. dag_id=fetch_and_store_google_books, task_id=create_table, run_id=scheduled__2024-06-24T00:00:00+00:00, execution_date=20240624T000000, start_date=20241211T211806, end_date=20241211T211806
[2024-12-11T21:18:06.842+0000] {taskinstance.py:340} INFO - ::group::Post task execution logs
[2024-12-11T21:18:06.843+0000] {standard_task_runner.py:124} ERROR - Failed to execute job 695 for task create_table (connection to server at "172.18.0.3", port 5432 failed: FATAL:  database "google_books" does not exist
; 307)
Traceback (most recent call last):
  File "/home/airflow/.local/lib/python3.12/site-packages/airflow/task/task_runner/standard_task_runner.py", line 117, in _start_by_fork
    ret = args.func(args, dag=self.dag)
          ^^^^^^^^^^^^^^^^^^^^^^^^^^^^^
  File "/home/airflow/.local/lib/python3.12/site-packages/airflow/cli/cli_config.py", line 49, in command
    return func(*args, **kwargs)
           ^^^^^^^^^^^^^^^^^^^^^
  File "/home/airflow/.local/lib/python3.12/site-packages/airflow/utils/cli.py", line 116, in wrapper
    return f(*args, **kwargs)
           ^^^^^^^^^^^^^^^^^^
  File "/home/airflow/.local/lib/python3.12/site-packages/airflow/cli/commands/task_command.py", line 483, in task_run
    task_return_code = _run_task_by_selected_method(args, _dag, ti)
                       ^^^^^^^^^^^^^^^^^^^^^^^^^^^^^^^^^^^^^^^^^^^^
  File "/home/airflow/.local/lib/python3.12/site-packages/airflow/cli/commands/task_command.py", line 256, in _run_task_by_selected_method
    return _run_raw_task(args, ti)
           ^^^^^^^^^^^^^^^^^^^^^^^
  File "/home/airflow/.local/lib/python3.12/site-packages/airflow/cli/commands/task_command.py", line 341, in _run_raw_task
    return ti._run_raw_task(
           ^^^^^^^^^^^^^^^^^
  File "/home/airflow/.local/lib/python3.12/site-packages/airflow/utils/session.py", line 97, in wrapper
    return func(*args, session=session, **kwargs)
           ^^^^^^^^^^^^^^^^^^^^^^^^^^^^^^^^^^^^^^
  File "/home/airflow/.local/lib/python3.12/site-packages/airflow/models/taskinstance.py", line 3005, in _run_raw_task
    return _run_raw_task(
           ^^^^^^^^^^^^^^
  File "/home/airflow/.local/lib/python3.12/site-packages/airflow/models/taskinstance.py", line 273, in _run_raw_task
    TaskInstance._execute_task_with_callbacks(
  File "/home/airflow/.local/lib/python3.12/site-packages/airflow/models/taskinstance.py", line 3159, in _execute_task_with_callbacks
    result = self._execute_task(context, task_orig)
             ^^^^^^^^^^^^^^^^^^^^^^^^^^^^^^^^^^^^^^
  File "/home/airflow/.local/lib/python3.12/site-packages/airflow/models/taskinstance.py", line 3183, in _execute_task
    return _execute_task(self, context, task_orig)
           ^^^^^^^^^^^^^^^^^^^^^^^^^^^^^^^^^^^^^^^
  File "/home/airflow/.local/lib/python3.12/site-packages/airflow/models/taskinstance.py", line 767, in _execute_task
    result = _execute_callable(context=context, **execute_callable_kwargs)
             ^^^^^^^^^^^^^^^^^^^^^^^^^^^^^^^^^^^^^^^^^^^^^^^^^^^^^^^^^^^^^
  File "/home/airflow/.local/lib/python3.12/site-packages/airflow/models/taskinstance.py", line 733, in _execute_callable
    return ExecutionCallableRunner(
           ^^^^^^^^^^^^^^^^^^^^^^^^
  File "/home/airflow/.local/lib/python3.12/site-packages/airflow/utils/operator_helpers.py", line 252, in run
    return self.func(*args, **kwargs)
           ^^^^^^^^^^^^^^^^^^^^^^^^^^
  File "/home/airflow/.local/lib/python3.12/site-packages/airflow/models/baseoperator.py", line 417, in wrapper
    return func(self, *args, **kwargs)
           ^^^^^^^^^^^^^^^^^^^^^^^^^^^
  File "/home/airflow/.local/lib/python3.12/site-packages/airflow/providers/common/sql/operators/sql.py", line 284, in execute
    output = hook.run(
             ^^^^^^^^^
  File "/home/airflow/.local/lib/python3.12/site-packages/airflow/providers/common/sql/hooks/sql.py", line 485, in run
    with self._create_autocommit_connection(autocommit) as conn:
         ^^^^^^^^^^^^^^^^^^^^^^^^^^^^^^^^^^^^^^^^^^^^^^
  File "/usr/local/lib/python3.12/contextlib.py", line 137, in __enter__
    return next(self.gen)
           ^^^^^^^^^^^^^^
  File "/home/airflow/.local/lib/python3.12/site-packages/airflow/providers/common/sql/hooks/sql.py", line 609, in _create_autocommit_connection
    with closing(self.get_conn()) as conn:
                 ^^^^^^^^^^^^^^^
  File "/home/airflow/.local/lib/python3.12/site-packages/airflow/providers/postgres/hooks/postgres.py", line 181, in get_conn
    self.conn = psycopg2.connect(**conn_args)
                ^^^^^^^^^^^^^^^^^^^^^^^^^^^^^
  File "/home/airflow/.local/lib/python3.12/site-packages/psycopg2/__init__.py", line 122, in connect
    conn = _connect(dsn, connection_factory=connection_factory, **kwasync)
           ^^^^^^^^^^^^^^^^^^^^^^^^^^^^^^^^^^^^^^^^^^^^^^^^^^^^^^^^^^^^^^^
psycopg2.OperationalError: connection to server at "172.18.0.3", port 5432 failed: FATAL:  database "google_books" does not exist

[2024-12-11T21:18:06.864+0000] {local_task_job_runner.py:266} INFO - Task exited with return code 1
[2024-12-11T21:18:06.873+0000] {local_task_job_runner.py:245} INFO - ::endgroup::
